<?xml version="1.0"?>

<robot name="myrobot2">

    <!-- base_footlink-->
    <link name="base_footprint"/>

    <!-- base link-->
    <link name="base_link">
        <visual>
            <origin xyz="0.0 0.0 0.0" rpy="0.0 0.0 0.0"/>
            <geometry>
                <mesh filename="package://myrobot2_description/meshes/base.STL"/>
            </geometry>
        </visual>
    </link>
    <joint name="base_joint" type="fixed">
        <parent link="base_footprint"/>
        <child link="base_link"/>
        <origin xyz="0.0 0.0 0.055" rpy="0.0 0.0 0.0"/>   
    </joint>
     
    <!-- wheel right link-->
    <link name="wheel_right_link">
        <visual>
            <origin xyz="0.0 0.0 0.0" rpy="1.57 0.0 0.0"/>
            <geometry>
                <mesh filename="package://myrobot2_description/meshes/right_wheel.STL"/>
            </geometry>
        </visual>
    </link>
    <joint name="wheel_right_joint" type="continuous">
        <parent link="base_link"/>
        <child link="wheel_right_link"/>
        <origin xyz="0.0 0.0 0.0" rpy="0.0 -0.45 0.0"/> 
        <axis xyz="0.0 1.0 0.0"/>  
    </joint>
    
    <!-- wheel left link-->
    <link name="wheel_left_link">
        <visual>
            <origin xyz="0.0 0.0 0.0" rpy="-1.57 0.0 0.0"/>
            <geometry>
                <mesh filename="package://myrobot2_description/meshes/left_wheel.STL"/>
            </geometry>
        </visual>
    </link>
    <joint name="wheel_left_joint" type="continuous">
        <parent link="base_link"/>
        <child link="wheel_left_link"/>
        <origin xyz="0.0 0.0 0.0" rpy="0.0 0.45 0.0"/> 
        <axis xyz="0.0 1.0 0.0"/>  
    </joint>


</robot>
